### 一、引发和创建异常

##### 自主引发异常
* raise语句

引发异常，可用raise语句，并将一个类(必须是Exception的子类)或实例作为参数。将类作为参数时，将自动创建一个实例。

下面的例子使用内置异常类型Exception

```python
raise Exception
Traceback (most recent call last):
  File "/Users/异常/test.py", line 1, in <module>
    raise Exception
Exception
```

```python
raise Exception("hyperdrive overload")
Traceback (most recent call last):
  File "/Users/异常/test.py", line 1, in <module>
    raise Exception("hyperdrive overload")
Exception: hyperdrive overload
```

第一个示例，引发的是普通异常，没有指出出现了什么错误。

第二个示例，添加了错误消息:hyperdrive overload

有很多内置的异常类，下面描述最重要的几个:

| 类名 | 描述 |
|:-- |:-- |
| Exception | 几乎所有的异常类都是从它派生而来 |
| AtrributeError | 引用属性或给它赋值失败时引发 |
| OSError | 操作系统不能执行指定的任务(如打开文件)时引发，有多个子类 |
| IndexError | 使用序列中不存在的索引时引发，为LookupError的子类 |
| KeyError | 使用映射中不存在的键时引发，为LookupError的子类 |
| NameError | 找不到名称(变量)时引发 |
| SyntaxError | 代码不正确引发 |
| TypeError | 将内置操作或函数用于类型不正确的对象时引发 |
| ValueError | 将内置操作或函数用于这样的对象时引发:其类型正确但包含的值不合适 |
| ZeroDivisionError | 在除法或求模运算的时二个参数为0时引发 |


##### 创建异常

有时候需要自己创建异常类。如何创建异常类？

就像创建其他类一样，但务必直接或间接地继承Exception(这以为这从任何内置异常类派生都可以)。

举例:

```python
class SomeCustomException(Exception):
    pass
```

### 二、如何处理异常

##### 捕获异常
对异常进行处理，通常称之为捕获异常。一般使用try/except语句。

```python
try:
    num1=int(input("分子:"))
    num2=int(input("分母:"))
    print(num1/num2)
except ZeroDivisionError:
    print("分母不能为0")
```

---
注意:

异常从函数向外传播到调用函数的地方。如果在这里也没有被捕获，异常将向程序的最顶层传播。这意味着你可使用try/except来捕获他人所编写函数引发的异常。

---

捕获异常后，如果要重新引发它(即继续向上传播)，可调用raise且不提供任何参数(也可显式地提供捕获到的异常)。

举例一个能够"抑制"异常ZeroDivisionError的计算器类。如果启用了这种功能，计算器将打印一条错误消息，而不让异常继续传播。

在与用户交互的会话中使用这个计算器时，抑制异常很有用；但在程序内部使用，引发异常是更加的选择(此时应关闭"抑制"功能)

```python
class MuffledCalculator:
    muffled=False
    def calc(self,expr):
        try:
            return eval(expr)
        except ZeroDivisionError:
            if self.muffled:
                print("Division by zero is illegal")
            else:
                raise
```

-----
注意:

发生除0行为时，如果启用了"抑制"功能，方法clac将(隐式地)返回None。换言之，如果启用了抑制功能，就不应该依赖返回值。

---

上面代码可以看到，关闭抑制功能时，捕获了异常ZeroDivisionError，但继续向上传播它。

如果无法处理异常，在except子句中使用不带参数的raise通常是不错的原则，但有时候你可能想引发别的异常。在这种情况下，导致进入except子句的异常将被作为异常上下文存储起来，并出现在最终的错误消息中，如下所示：

```Python
class MuffledCalculator:
    muffled=False
    def calc(self,expr):
        try:
            return eval(expr)
        except ZeroDivisionError:
            if self.muffled:
                print("Division by zero is illegal")
            else:
                raise ValueError
calculator=MuffledCalculator()
print(calculator.calc("10/0"))
```

引发的ZeroDivisionError如下:

```Python
Traceback (most recent call last):
  File "/Users//test.py", line 13, in calc
    return eval(expr)
  File "<string>", line 1, in <module>
ZeroDivisionError: division by zero
```

在处理上述异常时，引发了另外一个异常:

```Python
During handling of the above exception, another exception occurred:
Traceback (most recent call last):
  File "/Userstest.py", line 20, in <module>
    print(calculator.calc("10/0"))
  File "/Users//test.py", line 18, in calc
    raise ValueError
ValueError
```

可使用raise...from...语句来提供自己的异常上下文，也可使用None来禁用上下文

```Python
class MuffledCalculator:
    muffled=False
    def calc(self,expr):
        try:
            return eval(expr)
        except ZeroDivisionError:
            if self.muffled:
                print("Division by zero is illegal")
            else:
                raise ValueError from None
calculator=MuffledCalculator()
print(calculator.calc("10/0"))
```

输出结果如下:

```Python
Traceback (most recent call last):
  File "/Users//test.py", line 20, in <module>
    print(calculator.calc("10/0"))
  File "/Users/test.py", line 18, in calc
    raise ValueError from None
ValueError
```

##### 多分支:多个except子句
* 如果异常不止一种类型,该如何处理？

捕获异常中的例子中，输入一个非数字值，将引发另一种异常。但是程序中的except子句只捕获ZeroDivisionError异常，这种值类型错误的异常会成为漏网之鱼，导致程序终止。

为同时捕获这种异常，可在try/except语句中再添加一个except子句

```Python
try:
    num1=int(input("分子:"))
    num2=int(input("分母:"))
    print(num1/num2)
except ZeroDivisionError:
    print("分母不能为0")
except TypeError:
    print("只能输入数字")
```

* 如果要使用一个except子句捕获多种异常怎么处理呢？

可以用一个元组指定这些异常，如下所示:

```Python
try:
    num1=int(input("分子:"))
    num2=int(input("分母:"))
    print(num1/num2)
except (ZeroDivisionError,TypeError,NameError):
    print("输入值有误")
```

不过这种错误的处理方式，对打印错误消息帮助不大。

另一种方法是不断要求用户输入数组知道能够执行除法运算为止，可用下面的else语句实现。


##### 捕获对象

要在except子句中访问异常对象本身，可使用两个而不是一个参数。(注意:即便是在捕获多个异常的时候，也只向except提供了一个参数--一个元组)需要让程序继续运行并记录错误(可能只是向用户显示)时，可使用这个方法。

* 举个例子:

```Python
try:
    num1=int(input("分子:"))
    num2=int(input("分母:"))
    print(num1/num2)
except (ZeroDivisionError,TypeError) as e:
    print(e)
```

在这个小程序中，except子句也捕获两种异常，但由于同时显式地捕获了对象本身。因此可将其打印出来，让用户在知道发生了什么情况。


---
注意:

针对一些未预测无法被try/except捕获到的异常，可以直接使用try...except方法，except不用指定任何异常类。

但是像这样捕获所有的异常很危险，因为这不仅会异常你那个有准备的错误，还会隐藏一些没有考虑到的错误。这还将捕获用户使用Ctrl+C终止执行的企图，调用函数sys.exit()来终止执行的企图等。

在大多数情况下，更好的选择是使用except Exception as e并对异常对象进行检查。这样做将不是从Exception派生出来的为数不多的异常称为漏网之鱼，其中包括SystemExit和KeyboardInterrupt，因为他们是从BaseException(Exception的超类)派生而来的。

---


##### else语句

在有些情况，在没有出现异常时执行一个代码块很有用。为此，可像条件语句和循环一样，给try/except语句添加一个else子句。

* 举个例子

```python
try:
    print("A simple test")
except:
    print("What's Wrong?")
else:
    print("ah...")
```

运行后的结果为:

```python
A simple test
ah...
```

通过使用else子句，可实现

```python
while True:
    try:
        num1=int(input("分子:"))
        num2=int(input("分母:"))
        print(num1/num2)
    except:
        print("输入有误")
    else:
        break
```

在这里，仅当没有引发异常的时，才会调出循环(这是由else子句中的break语句实现的)。换言之，只要出现错误，程序就会要求用户提供新的输入，直到输入正确的值为止。

前面说过，一种更佳的方案是使用except子句来捕获所有属于类Exception(或其子类)的异常。因为你不能完全确定这将捕获所有的异常，因为try/except语句中的代码可能使用旧式的字符串异常或引发并非从Exception派生而来的异常。然而如果使用except Exception as e,就可在这个小型除法程序中打印更有用的错误消息:

```Python
while True:
    try:
        num1=int(input("分子:"))
        num2=int(input("分母:"))
        print(num1/num2)
    except Exception as e:
        print("无效输入:",e)
        print("输入有误")
    else:
        break
```

##### finally子句

finally子句用于在发生异常时执行清理工作。这个子句是与try子句配套的。

```Python
x=None
try:
    x=1/0
finally:
    print("cleaning up")
    del x
```

输入结果如下

```Python
Traceback (most recent call last):
cleaning up
  File "/Users//test.py", line 42, in <module>
    x=1/0
ZeroDivisionError: division by zero
```

在上述例子中，不管try子句中发生什么异常，都将执行finally子句。

虽然使用del来删除变量是相当愚蠢的清理措施，但finally子句非常适合用于确保文件或网络套接字等得以关闭。(以后会介绍)

为何在try子句之前初始化x呢？

因为如果不这样做，ZeroDivisionError将导致根本没有机会给x赋值，进而导致在finally子句中对其执行del时引发未捕获的异常。


### 三、异常和函数

异常和函数有着天然的联系。如果不处理函数中引发的异常，它将向上传播到调用函数的地方。如果在那里也未得到处理，异常将继续传播，直至到达主程序(全局作用域)。如果主程序中也没有异常处理程序，程序将终止并显示栈跟踪消息。

举个例子:

```Python
def faulty():
    raise Exception("Something is wrong")

def ignore_exception():
    faulty()

def handle_exception():
    try:
        faulty()
    except:
        print("Exception handled")
```

运行测试一:

```Python
ignore_exception()
#输出结果
Traceback (most recent call last):
  File "/Users/test.py", line 59, in <module>
    ignore_exception()
  File "/Users/test.py", line 51, in ignore_exception
    faulty()
  File "/Users/test.py", line 48, in faulty
    raise Exception("Something is wrong")
Exception: Something is wrong
```

运行测试二:

```Python
handle_exception()
#输出结果
Exception handled
```

如上所示，faulty中引发的异常依次从faulty和ignore_exception向外传播，最终导致显示一条栈跟踪消息。调用ignore_exception，并被这里的try/except语句处理。


### 四、异常之禅

如果你知道代码可能引发某种异常，且不希望出现在这种异常时程序终止并显示栈跟踪消息，可添加必要的try/except或try/finally语句(或结合使用)来处理它。

有时候，可使用条件语句来达成异常处理实现的目标，但这样编写出来的代码可能不那么自然，可读性也没那么高。

另一方面，有些任务使用if/else完成是看似很自然，但实际上使用try/except来完成要好得多。下面来看两个示例:

##### 检查字典是否存在某个键

假设有一个字典，你要在指定的键存在时打印与之相关联的值，否则什么都不做。

字典如下:

```python
info={"name":"Jane","age":23,"occupation":"IT"}
```

* 用if/else实现:

```python
def describe_person(person):
    print("Description of:",person["name"])
    print("Age:",person["age"])
    if "occupation:" in person:
        print("Occupation:",person["occupation"])
```

代码虽然很直观，但效率不高，因为它必须两次查找"occupation"键:一次查找这个键是否存在(在条件中)，另一次获取这个键关联的值，以便将其打印出来。



* 用try/except实现

```python
def describe_person(person):
    print("Description of:",person["name"])
    print("Age:",person["age"])
    try:
        print("Occupation:",person["occupation"])
    except KeyError:
        pass
```

这里函数直接假设存在"occupation"键:如果这种假设正确，直接获取并打印值，而无需检查这个键是否存在；如果这种假设不存在，将引发KeyError异常，而except子句将捕获这个异常。


##### 检查对象是否包含某个属性

当然也可以用try/except检查对象是否包含特定的属性:

```python
try:
    obj.write
except AttributeError:
    print("The object is not writeable")
else:
    print("The object is writeable")
```

在这里try子句只是访问属性write，而没有使用它来做任何事情。如果引发了AttributeError异常，说明对象没有属性write，否则就说明有这个属性。

---
注意:

这里在效率方面的提高并不大(实际上是微乎其微)，一般而言，除非程序存在性能方面的问题，否则不应过多考虑这样的优化。

关键在很多情况下，相比于使用if/else，使用try/except语句更自然，也更符合Python的风格。请养成尽可能使用try/except语句。

---


### 五、不那么异常的情况

如果只是想发出警告，指出情况偏离了正轨，可使用模块warning中的函数warn。

举个例子:

```python
from warnings import warn
warn("这里可能出错了!")
```

输出结果如下:

```python
__main__:1: UserWarning: 这里出错了
```

警告只显示一次。如果再次运行最后一行代码，什么也不会发生。

如果其他代码在使用你的模块，可使用模块warning中的函数filterwarnings来抑制你发出的警告(或特定类型的警告)，并指定要采取的措施，如"error"或"ignore"。

* igonre

```python
from warnings import warn
from warnings import filterwarnings
filterwarnings("ignore")
warn("igonre:这里可能要出错了")
```
使用ignore会忽略掉警告，什么也不会发生

* error

```python
filterwarnings("error")
warn("error:这里可能要出错了")
```

运行结果

```python
UserWarning: error:这里可能要出错了
```

如上所见，引发的异常为UserWarining。发出警告时，可指定将引发的异常(即警告类别)，但必须是Warning的子类。如果将警告转换为错误，将使用你指定的异常，另外还可根据异常来过滤掉特定类型的警告。


```python
filterwarnings("error")
warn("这里可能要出错了",DeprecationWarning)
```

输出结果

```python
DeprecationWarning: 这里可能要出错了
```

### 六、asser断言

一般用法是:

```python
assert condition
```

用来让程序测试这个condition，如果condition为false，那么raise一个AssertionError出来。逻辑上等同于：

```python
if not condition:
    raise AssertionError()
```

举个例子:

```python
assert 1==0
```

输出结果为:

```python
Traceback (most recent call last):
  File "<pyshell#1>", line 1, in <module>
    assert 1==0
AssertionError
```


### 七、总结

1.异常对象

异常情况(如发生错误)是用异常对象表示的。对于异常情况，有多种处理方式；如果忽略，将导致程序终止。

2.引发异常

可使用raise语句来引发异常。它将一个异常类或者异常示例作为参数，但你也可以提供两个参数(异常和错误消息)。如果在except子句中调用raise时没有提供任何参数，它将重新引发该子句捕获的异常。

3.自定义的异常类

可以通过从Exception派生来创建自定义的异常

4.捕获异常

要捕获异常，可在try语句中使用except子句。在except子句中，如果没有指定异常类，将捕获所有的异常。你可以指定多个异常类，方法是将它们放在元组中，如果向except提供两个参数(except...as...)，第二个参数将关联到异常对象。在同一条try/except语句中，可包含多个except子句，以便对不同的异常采取不同的措施。

5.else子句

除except子句外，还可使用else子句，它在主try块中没有引发异常时执行。

6.finally

要确保代码块(如清理代码)无论是否引发异常都将执行，可使用try/finally，并将代码块放在finally子句中。

7.异常和函数

在函数中引发异常时，异常将船舶到调用函数的地方(对方法来说亦是如此)

8.警告

警告类似于异常，但(通常)只打印一条错误信息。你可指定警告类别，它们是warning的子类

9.assert断言

断言就是判断条件是否成立，如果不成立，会出发AssertionError



9.总结try..except
1：把错误处理和真正的工作分开来

2：代码更易组织，更清晰，复杂的工作任务更容易实现；

3：毫无疑问，更安全了，不至于由于一些小的疏忽而使程序意外崩溃了；
